Traceback (most recent call last):
  File "/Library/Frameworks/Python.framework/Versions/3.11/lib/python3.11/site-packages/jupyter_cache/executors/utils.py", line 51, in single_nb_execution
    executenb(
  File "/Library/Frameworks/Python.framework/Versions/3.11/lib/python3.11/site-packages/nbclient/client.py", line 1204, in execute
    return NotebookClient(nb=nb, resources=resources, km=km, **kwargs).execute()
           ^^^^^^^^^^^^^^^^^^^^^^^^^^^^^^^^^^^^^^^^^^^^^^^^^^^^^^^^^^^^^^^^^^^^^
  File "/Library/Frameworks/Python.framework/Versions/3.11/lib/python3.11/site-packages/nbclient/util.py", line 84, in wrapped
    return just_run(coro(*args, **kwargs))
           ^^^^^^^^^^^^^^^^^^^^^^^^^^^^^^^
  File "/Library/Frameworks/Python.framework/Versions/3.11/lib/python3.11/site-packages/nbclient/util.py", line 62, in just_run
    return loop.run_until_complete(coro)
           ^^^^^^^^^^^^^^^^^^^^^^^^^^^^^
  File "/Library/Frameworks/Python.framework/Versions/3.11/lib/python3.11/asyncio/base_events.py", line 650, in run_until_complete
    return future.result()
           ^^^^^^^^^^^^^^^
  File "/Library/Frameworks/Python.framework/Versions/3.11/lib/python3.11/contextlib.py", line 222, in __aexit__
    await self.gen.athrow(typ, value, traceback)
  File "/Library/Frameworks/Python.framework/Versions/3.11/lib/python3.11/site-packages/nbclient/client.py", line 608, in async_setup_kernel
    yield
  File "/Library/Frameworks/Python.framework/Versions/3.11/lib/python3.11/site-packages/nbclient/client.py", line 663, in async_execute
    await self.async_execute_cell(
  File "/Library/Frameworks/Python.framework/Versions/3.11/lib/python3.11/site-packages/nbclient/client.py", line 965, in async_execute_cell
    await self._check_raise_for_error(cell, cell_index, exec_reply)
  File "/Library/Frameworks/Python.framework/Versions/3.11/lib/python3.11/site-packages/nbclient/client.py", line 862, in _check_raise_for_error
    raise CellExecutionError.from_cell_and_msg(cell, exec_reply_content)
nbclient.exceptions.CellExecutionError: An error occurred while executing the following cell:
------------------
from datetime import date, timedelta

import sys
sys.path.append('../../')
from newscrape.config import CONFIG; CONFIG.load('../../config.toml')
from newscrape.db import NewsDBClient
from newscrape.webdriver import WebDriver
from newscrape.scraper.headline import NewsHeadlinePicker
from newscrape.scraper import NewsScraper
------------------

[0;31m---------------------------------------------------------------------------[0m
[0;31mModuleNotFoundError[0m                       Traceback (most recent call last)
Cell [0;32mIn [1], line 5[0m
[1;32m      3[0m [38;5;28;01mimport[39;00m [38;5;21;01msys[39;00m
[1;32m      4[0m sys[38;5;241m.[39mpath[38;5;241m.[39mappend([38;5;124m'[39m[38;5;124m../../[39m[38;5;124m'[39m)
[0;32m----> 5[0m [38;5;28;01mfrom[39;00m [38;5;21;01mnewscrape[39;00m[38;5;21;01m.[39;00m[38;5;21;01mconfig[39;00m [38;5;28;01mimport[39;00m CONFIG; CONFIG[38;5;241m.[39mload([38;5;124m'[39m[38;5;124m../../config.toml[39m[38;5;124m'[39m)
[1;32m      6[0m [38;5;28;01mfrom[39;00m [38;5;21;01mnewscrape[39;00m[38;5;21;01m.[39;00m[38;5;21;01mdb[39;00m [38;5;28;01mimport[39;00m NewsDBClient
[1;32m      7[0m [38;5;28;01mfrom[39;00m [38;5;21;01mnewscrape[39;00m[38;5;21;01m.[39;00m[38;5;21;01mwebdriver[39;00m [38;5;28;01mimport[39;00m WebDriver

File [0;32m~/Developer/py-projects/news-scraper/book/quick-start/../../newscrape/config.py:5[0m
[1;32m      3[0m [38;5;28;01mfrom[39;00m [38;5;21;01mpathlib[39;00m [38;5;28;01mimport[39;00m Path
[1;32m      4[0m [38;5;28;01mimport[39;00m [38;5;21;01mtomllib[39;00m
[0;32m----> 5[0m [38;5;28;01mfrom[39;00m [38;5;21;01mxpyutils[39;00m [38;5;28;01mimport[39;00m lazy_property, singleton
[1;32m      7[0m [38;5;129m@singleton[39m
[1;32m      8[0m [38;5;28;01mclass[39;00m [38;5;21;01mProjectConfig[39;00m:
[1;32m     10[0m     [38;5;28;01mdef[39;00m [38;5;21m__init__[39m([38;5;28mself[39m) [38;5;241m-[39m[38;5;241m>[39m [38;5;28;01mNone[39;00m:

[0;31mModuleNotFoundError[0m: No module named 'xpyutils'
ModuleNotFoundError: No module named 'xpyutils'

